Workbook
Name AMO_TM: 'Project Basics & Benchmarks'!$C$12
Name AnnualCapEx_Benchmark: CapEx!$O$42
Name AnnualCapEx_Benchmark_withMaintenance: CapEx!$O$44
Name AnnualCapEx_NewTech: CapEx!$G$42
Name AnnualCapEx_NewTech_withMaintenance: CapEx!$G$44
Name AnnualConstructionCapEx_Benchmark: CapEx!$O$36
Name AnnualConstructionCapEx_NewTech: CapEx!$G$36
Name AnnualEnergyCost_Benchmark: OpEx!$M$88
Name AnnualEnergyCost_NewTech: OpEx!$F$88
Name AnnualLaborCost_Benchmark: OpEx!$M$86
Name AnnualLaborCost_NewTech: OpEx!$F$86
Name AnnualMatCost_Benchmark: OpEx!$M$87
Name AnnualMatCost_NewTech: OpEx!$F$87
Name AnnualNonProcessCapEx_Benchmark: CapEx!$O$31
Name AnnualNonProcessCapEx_NewTech: CapEx!$G$31
Name AnnualOpEx_Benchmark: OpEx!$M$90
Name AnnualOpEx_NewTech: OpEx!$F$90
Name AnnualOtherCapEx_Benchmark: CapEx!$O$41
Name AnnualOtherCapEx_NewTech: CapEx!$G$41
Name AnnualOtherRecurring_Benchmark: OpEx!$M$89
Name AnnualOtherRecurring_NewTech: OpEx!$F$89
Name AnnualOverheadCost_Benchmark: OpEx!#REF!
Name AnnualOverheadCost_NewTech: OpEx!#REF!
Name AnnualProcessCapEx_Benchmark: CapEx!$O$26
Name AnnualProcessCapEx_NewTech: CapEx!$G$26
Name AnnualUsePhaseEmissions_Current: 'Use Phase Energy'!$J$34
Name AnnualUsePhaseEmissions_Hypothetical: 'Use Phase Energy'!$O$34
Name AnnualUsePhaseEnergy_Current: 'Use Phase Energy'!$H$34
Name AnnualUsePhaseEnergy_Hypoth: 'Use Phase Energy'!$M$34
Name BasicsBenchmarks: 'Project Basics & Benchmarks'!$B$5
Name Benchmark_Apps: 'Project Basics & Benchmarks'!$E$30
Name Benchmark_Status: 'Project Basics & Benchmarks'!$F$30
Name CH4_GWP: 'GWP Ref Tables'!$E$9
Name Challenges_Additive_Manufacturing: 'Dropdown Menu Options'!$D$54:$M$54
Name Challenges_Advanced_Materials: 'Dropdown Menu Options'!$D$55:$M$55
Name Challenges_Advanced_Sensors: 'Dropdown Menu Options'!$D$56:$M$56
Name Challenges_CHP: 'Dropdown Menu Options'!$D$57:$M$57
Name Challenges_Clean_Water: 'Dropdown Menu Options'!$D$68:$M$68
Name Challenges_Composite_Materials: 'Dropdown Menu Options'!$D$58:$M$58
Name Challenges_Critical_Materials: 'Dropdown Menu Options'!$D$59:$M$59
Name Challenges_Cybersecurity: 'Dropdown Menu Options'!$D$69:$M$69
Name Challenges_Energy_Efficient_Computing: 'Dropdown Menu Options'!$D$70:$M$70
Name Challenges_Materials_Harsh: 'Dropdown Menu Options'!$D$61:$M$61
Name Challenges_Motor_Driven_Systems: 'Dropdown Menu Options'!$D$71:$M$71
Name Challenges_Other: 'Dropdown Menu Options'!$D$72:$M$72
Name Challenges_Process_Heating: 'Dropdown Menu Options'!$D$62:$M$62
Name Challenges_Process_Intensification: 'Dropdown Menu Options'!$D$63:$M$63
Name Challenges_Roll_to_Roll_Processing: 'Dropdown Menu Options'!$D$64:$M$64
Name Challenges_Sustainable_Manufacturing: 'Dropdown Menu Options'!$D$65:$M$65
Name Challenges_Thermal_Conversion_Materials: 'Dropdown Menu Options'!$D$60:$M$60
Name Challenges_Waste_Heat_Recovery: 'Dropdown Menu Options'!$D$66:$M$66
Name Challenges_Wide_Bandgap_Semiconductors: 'Dropdown Menu Options'!$D$67:$M$67
Name Commercial_Benchmark: 'Project Basics & Benchmarks'!$D$30
Name CurrentMarketShare_Benchmark: Market!$E$21
Name CurrentMarketShare_NewTech: Market!$E$20
Name CurrentMarketShare_OtherTech: Market!$E$22
Name DataPlanning: #REF!
Name e: '[1]Project Basics & Benchmarks'!$D$41
Name EIA: 'EIA Ref Tables'!$B$3
Name EndUse_Product: 'Project Basics & Benchmarks'!$C$24

Sheet TECHTEST Landing Page
C1: U.S. DEPARTMENT OF ENERGY (DOE) OFFICE OF ENERGY EFFICIENCY AND RENEWABLE ENERGY (EERE)
C2: Techno-economic, Energy & Carbon Heuristic Tool for Early Stage Technologies (TECHTEST)
C3: Version 1.0
C4: Release: February 19, 2023
C6: What can I expect from TECHTEST?
C7: • TECHTEST is a tool that collects specific categorical cost, energy, and emissions data about a new technology and the associated benchmark technology for comparison. • TECHTEST will develop a series of charts and tables that will project the economic and sustainable viability of the product compared to its comparable current market technology. There are two ways to fill out TECHTEST:
C12: • Full Analytical Approach: Review each section of the lifecycle separately, enter more granular data. (Recommended for first time users)
C13: • Rapid Data Entry Approach: Abbreviated approach, little to no explanation of steps. (Recommended for multiple scenario testing)
C15: TECHTEST Data
C16: •TECHTEST utilizes CO2-e and costs associated with materials and energy sources to fill out the back end of the calculation. The cost vectors and corresponding sources can be found in the link below:
C17: Link to energy/cost data tables.
C18: Link to global warming potential data tables
... C31: Other Cells: Not intended for editing

Sheet Full Entry Home Page
B2: Method 1. Full Analytical Approach
C4: This method generates results from scratch, starting with source data. This is the recommended method for most users who are starting from scratch. If you are beginning with a complete cost, energy, and emissions analysis in another format and simply need to "port" data into the IPA template, you can consider the Rapid Data Entry Approach. To estimate the potential cost & environmental impacts of a new technology, complete all green input tabs. You will input data for both the new technology (being developed in this project) and for the commercial benchmark technology (that you will be comparing to). Follow the instructions provided to enter data in cells that are shaded blue (text or numeric entry) or gold (dropdown menu selection). Be as complete and specific as possible in your data entries. Document assumptions, references, calculations, and estimation methods used. It works best to complete tabs in order from left to right - but it is OK to fill them out of order, if needed. If filling tabs out-of-order, follow instructions carefully to enter certain data points in earlier tabs as needed, rather than over-writing formulae in the sheet. This will avoid problems with duplicate data entries, cell reference errors, and named variables. Data should be entered ONLY in the blue and gold cells.
C5: Data input tabs for the Full Analytical Approach are linked below:
B7: 1 | C7: Project Basics & Benchmarks (Tier 1)
B8: 2 | C8: Market (Tier 2)
B9: 3 | C9: Functional Unit (Tier 2)
B10: 4 | C10: Raw Materials (Including: Embodied Energy, Emissions, and Costs (Tier 2))
B11: 5 | C11: Manufacturing Energy (Manufacturing Phase Energy & Emissions (Tier 2))
B12: 6 | C12: Use Phase Energy (Energy andEmissions (Tier 2))
B13: 7 | C13: Grid Mix
B14: 8 | C14: CapEx (Tier 2)
B15: 9 | C15: OpEx (Tier 2)
C16: As data fields in the input tabs are filled, summary result tables and plots will automatically start to appear in the two results output tabs (shaded navy blue). In these tabs, the new technology will be compared head-to-head with the commercial benchmark technology on an energy and cost basis. After completing all of the Input tabs, you can scroll through the Summary Results Output tabs to view results summaries in tabular and graphical "dashboard" formats. Notes that the accuracy of the generated tables and plots depends on the completeness of data in the Input tabs. After reviewing, you may wish to go back to the input tabs to add further detail and improve the quality of the results.
C17: The results summary output tabs for the Full Analytical Approach are linked below:
B18: 1 | C18: Results Summary Tables
B19: 2 | C19: Graphical Results Dashboard

Sheet Rapid Data Entry Home Page
B2: Method 2. Rapid Data Entry Approach
C4: The Rapid Data Entry Approach, which requires high-level data entries only, is intended for users who have already completed an analysis in another format, but wish to quickly "port" results into TECHTEST to generate results tables and dashboards in the IPA format.
C5: It is also possible to mix-and-match the two approaches by partially completing the Rapid Data Entry sheet using available data, then making more detailed calculations in appropriate tabs of the Full Analytical Approach to estimate missing data. Results from Full Analytical tabs can be copied and pasted (as values) into appropriate cells of the Rapid Data Entry Approach to populate a complete dataset.
C6: To estimate the potential cost & environmental impacts of a new technology, first complete the two light-green Tier 1 data input tabs, also used in Method 1 (Project Basics and Benchmarks, and Performance Metrics). Then, skip ahead to the orange "Rapid Data Input" tab for Method 2. In this sheet, you will input high-level cost, energy, and emissions data for both the new technology (being developed in this project) and for the commercial benchmark technology (that you will be comparing to). Follow the instructions provided to enter data in cells that are shaded blue. Be as complete and specific as possible in your data entries. Document assumptions, references, calculations, and estimation methods used.
C7: Data input tabs for the Rapid Data Entry Method are linked below:
B9: 1 | C9: Project Basics and Benchmarks (Tier 1)
B10: 2 | C10: Rapid Data Input Sheet for Method 2 (Tier 2)
C12: As data fields in the input tabs are filled, summary result tables and plots will automatically start to appear in the Method 2 results output tabs (shaded deep red). In these tabs, the new technology will be compared head-to-head with the commercial benchmark technology on an energy and cost basis - in the same format as Method 1. Notes that the accuracy of the generated tables and plots depends on the completeness of data in the Input tabs. After reviewing, you may wish to go back to the input tabs to add further detail and improve the quality of the results.
C13: The results summary output tabs for the Rapid Data Entry Approach are linked below:
B14: 1 | C14: Results Summary Tables (Method 2)
B15: 2 | C15: Graphical Results Dashboard (Method 2)

Sheet Project Basics & Benchmarks
B1: U.S. DEPARTMENT OF ENERGY (DOE) OFFICE OF ENERGY EFFICIENCY AND RENEWABLE ENERGY (EERE)
B2: Techno-economic, Energy & Carbon Heuristic Tool for Early Stage Technologies (TECHTEST)
C4: Return to Full Entry Home Page | D4: Return to Rapid Data Entry Home Page
B5: Project & Technology Description
B7: Project Title | C7: Waste Heat Recovery Cooling in Beverage Manufacturing
B8: Lead Organization | C8: Hypothetical Organization
B9: Collaborative Partner(s) | C9: Staff
B10: Principal Investigator Name | C10: John Doe
B11: Principal Investigator Organization | C11: Hypotentical National Laboratory
B12: AMO Technology Manager | C12: Jane Doe
B13: Project Start | C13: 44927
B14: Project End | C14: 45658
B15: Funding Mechanism | C15: R&D Project
B16: =IF(C15="Consortium","Consortium Name:",IF(C15="FOA (Funding Opportunity Announcement)","FOA Title:",""))
B17: =IF(C15="FOA (Funding Opportunity Announcement)","FOA Topic Area (if multiple):","")
B18: =IF(C15="FOA (Funding Opportunity Announcement)","FOA Subtopic (if any):","")
B19: Technology Diagram (insert in cells to right) | C19: TBD
B20: Technology Benchmarking
B22: Define the generic market-end use product. If the new technology, commercial benchmark, other competing technologies produce different products that serve the same function and would be used in the same market, the generic market end-use product should be defined generally enough to encompass these different products or variations. For example, a Market End Use Product could be "automotive high strength steel" rather than the more specific "HSLA 350 steel produced by XYZ process." Defining a product and market that is too-specific may overly restrict the impact analysis.
B24: Generic Market End-Use Product*: | C24: Cooled Waste Water
C25: * The "generic" market end-use product should be defined generally enough to encompass the end-use products of all competing technologies (new technology, commercial benchmark, other competing technologies), if the end products are different but would be used to serve the same function. Specific differences in the end products or applications can be specified in the table below.
B27: Definitions of Competing Technologies and Products | D27: Technology Definition | E27: Specific Product or Application | F27: Technology Status
D28: Define the technology. | E28: Identify the end-use products and/or key applications for this technology, noting any differences. | F28: Is this technology a current typical technology, a state-of-the-art technology, or an emerging technology?
C29: New Technology (developed in this project) | D29: Waste Heat Recovery (Heat Pump) | E29: Cooled Waste Water | F29: Typical Technology
C30: Commercial Benchmark Technology | D30: Evaporative Condenser | E30: Cooled Waste Water | F30: Typical Technology
C31: Other Competing Technologies (list relevant technologies, separating by commas)
B33: Energy, Emissions & Cost Impact Drivers | D33: Note: This section examines emissions over the entire lifecycle.
B35: Energy & Emissions Impacts by Life Cycle Phase | C35: In your opinion, would this technology be likely to impact the energy and/or emissions associated with … | D35: Yes/No | E35: Mechanism (Explain why this technology would be likely to have an impact.)
C36: … raw materials used in the manufacturing process? | D36: No
C37: … manufacturing the end-use product? | D37: Yes | E37: Higher energy efficiency, no cooling water needed
C38: … using, transporting, or disposing of the end-use product? | D38: No
B40: Manufacturing Cost Impacts by Cost Component | C40: In your opinion, would this technology be likely to impact the manufacturing costs associated with … | D40: Yes/No | E40: Mechanism
C41: … capital equipment? | D41: No
C42: … raw materials used in manufacturing? | D42: No
C43: … energy used in manufacturing? | D43: No
C44: … manufacturing labor? | D44: No
B46: Impacts by Sector | C46: In your opinion, would this technology be likely to impact the following sectors (energy, emissions, or cost)? | D46: Yes/No | E46: Mechanism
B47: For each sector that would be impacted by the new technology, briefly describe the mechanisms of potential impacts. (Assume successful commercialization and adoption.) | C47: Mining | D47: No
C48: Manufacturing | D48: Yes | E48: Used to save energy in beverage manufacturing
C49: Transportation | D49: No
...

Sheet Functional Unit
B1: U.S. DEPARTMENT OF ENERGY (DOE) OFFICE OF ENERGY EFFICIENCY AND RENEWABLE ENERGY (EERE)
B2: Techno-economic, Energy & Carbon Heuristic Tool for Early Stage Technologies (TECHTEST)
B3: Functional Units and Reference Quantities
C4: Return to Planning Page
B5: An explanation of best practices for choosing a functional unit can be found in DOE's "Functional Units" short tutorial video:
B6: https://www.youtube.com/watch?v=6_5j8kTomOo&ab_channel=U.S.DepartmentofEnergy
B8: A Functional Unit defines the quantity of a product or product system based on the performance it delivers in its end-use application. The purpose of defining a performance-based functional unit is to facilitate accurate comparisons (of environmental or cost metrics) for disparate products or systems that serve the same final function. The functional unit can be used to objectively compare the new technology to the commercial benchmark technology. The process can be broken down into two steps:
B11: Describing the final function for the technology and defining the functional unit.
G12: Examples
B13: – If the technology is a production method, you can define the functional unit based on a quantity of product that the process creates. For Example: A steel smelting process could be defined based on its ability to produce 1 kg of automotive steel. – If the technology is a product, you can define the functional unit based on a quantitative measure of the intended function of the product. For Example: A light souce could be defined based on its ability to produce 1,000 lumens of brightness for 1,000 hours. | G13: The total volume of catalyst required to produce 1 ton of ethylene.
G14: The mass of steel required to produce an automotive B-pillar for an average mid-size sedan.
G15: All light bulbs required to produce 1,000 lumens of brightness over 100,000 hours.
G16: All shipping pallets required to deliver 100,000 lbs of product load at a dynamic load rating of 5,000 lbs.
B17: Step 1: Based on the functional unit, specify a reference quantity for the New Technology that can be compared to an equivalent reference quantity for the Commercial Benchmark Technology.
B18: Use the functional unit to specify a production reference quantity for the new technology, as shown in the examples below.
C20: Functional Unit Based Reference Quantity for the New Technology: | D20: 2 | E20: Million Gallons | F20: of | G20: Cooled Waste Water | H20: for New Technology
D21: Value | E21: Unit | G21: of Product
D22: Examples: | E22: 80 kg of new ethylene catalyst
E23: 1,000,000 lumen-hours produced by a new LED bulb
E24: 9 kg of dual-phase high strength steel
E25: 18 recycled polymer pallet shipping pallets in novel design
B27: Finally, specific the performance-equivalent production reference quantity for the commercial benchmark technology, as shown in the examples below. Note that this value may be the same or different from the reference quantity for the new technology. It depends on how you've defined your functional unit, and whether the new technology will serve as a drop-in replacement for the benchmark technology.
C29: Performance Equivalent Reference Quantity for the Commercial Benchmark: | D29: 2 | E29: =E20 -> Million Gallons | F29: of | G29: =IF(G20="","",G20) -> Cooled Waste Water | H29: for Commercial Benchmark Technology
D30: Value | E30: Unit | G30: of Product
D31: Examples: | E31: 90 kg of conventional ethylene catalyst
E32: 1,000,000 lumen-hours produced by a current typical lightbulb
E33: 13 kg of conventional mild steel
E34: 24 conventional wood stringer pallets
C35: Explain Differentiation in Functional Units
C36: =IF(D20<>D29,"The default assumption is that there will not be a difference in performance equivalence, make sure the difference can be explained by writing out the logic in the blue box below.","Proceed to Step 2 for Functional Unit review.") -> Proceed to Step 2 for Functional Unit review.
B41: Step 2: Verify the Performance Equivalency Summary of the Functional Unit for the New Technology and the Commerical Benchmark.
C44: Functional Unit
C45: =IF(ISBLANK(H12),"",H12)
C47: New Technology | G47: Commercial Benchmark
B48: Technology Name | C48: =New_Technology -> Waste Heat Recovery (Heat Pump) | G48: =Commercial_Benchmark -> Evaporative Condenser
B49: Specific Product | C49: =G20 -> Cooled Waste Water | G49: =G29 -> Cooled Waste Water
B50: Functional Unit Based Reference Qty. | C50: =D20 -> 2 | D50: =E20 -> Million Gallons | G50: =D29 -> 2 | H50: =E29 -> Million Gallons
C51: New Technology Production Equivalent | D51: (units) | G51: Benchmark Production Equivalent | H51: (units)
B53: Throughout this analysis, all energy consumption and cost data will be reported in terms of the functional unit based reference quantities derived above.
B55: References, Notes, and Assumptions
...

Sheet Raw Materials
B1: U.S. DEPARTMENT OF ENERGY (DOE) OFFICE OF ENERGY EFFICIENCY AND RENEWABLE ENERGY (EERE)
B2: Techno-economic, Energy & Carbon Heuristic Tool for Early Stage Technologies (TECHTEST)
E3: Return to Planning Page
B4: Raw Material Embodied Energy, Emissions, and Costs
B6: In this tab, you will estimate the embodied energy, embodied carbon, and cost for raw material inputs to manufacturing, for the New Technology (left) and for the Commercial Benchmark (right). Note that the technology definitions and product definitions are imported by default from the Benchmarking section of the "Project Basics" tab; and reference volumes are imported from the "Ref Volume" tab. If any edits to these values are needed, please modify in those tabs to ensure changes are carried through entire analysis.
C7: New Technology (at Industrial Scale) | M7: Commercial Benchmark
B8: Technology Name | C8: =New_Technology -> Waste Heat Recovery (Heat Pump) | L8: Technology Name | M8: =Commercial_Benchmark -> Evaporative Condenser
B9: Specific Product | C9: =New_Technology_Apps -> Cooled Waste Water | L9: Specific Product | M9: =Benchmark_Apps -> Cooled Waste Water
B10: Reference Volume | C10: =Ref_Volume -> 2 | D10: =Ref_Volume_Unit -> Million Gallons | L10: Reference Volume | M10: =Ref_Volume_Benchmark -> 2 | N10: =Ref_Volume_Unit -> Million Gallons
C11: (reference volume) | D11: (units) | M11: (reference volume) | N11: (units)
B13: List all significant input materials in the table below. Considering the reference volume specified in the prior tab (and shown above), specify for each input material the amount required to produce the reference quanity, as well as the specific embodied energy, specific embodied carbon*, and specific cost for each material. Follow the same process for the new technology (left) and commercial benchmark technology (right) to facilitate comparisons.
B14: Embodied energy and carbon for input materials may conveniently be estimated using NREL's Materials Flow Through Industry (MFI) tool (using the exact materials if available, or using similar "proxy" materials as an estimate). Indicate the specific MFI material names used for estimates (or other sources and assumptions) in the "References, Notes, and Assumptions" section below. The tool tab linked below can be used to easily extract embodied energy and carbon values from MFI results output. MFI embodied energy and carbon results can then be pasted as values in the Specific Embodied Energy column.
B15: Calculator Tool: Extracting Embodied Energy & Carbon from MFI
B16: New Technology - Raw Material Inputs | E16: Enter MFI embodied energy data in this column ↓ | F16: Enter MFI embodied carbon data in this column ↓ | L16: Commercial Benchmark - Raw Material Inputs | O16: Enter MFI embodied energy data in this column (if applicable) ↓ | P16: Enter MFI embodied carbon data in this column ↓
B17: Material Inputs (list) | C17: Amount of Material (to produce reference volume) | D17: unit | E17: Specific Embodied Energy (Btu/unit) (for this material) | F17: Specific Embodied Carbon (lbs CO2-eq/unit) (for this material) | G17: Specific Cost ($/unit) (for this material) | H17: Embodied Energy (MMBtu) (per reference volume of product) | I17: Embodied Carbon (lbs CO2-eq) (per reference volume of product) | J17: Cost ($) (per reference volume of product) | L17: Material Inputs (list) | M17: Amount of Material (to produce reference volume) | N17: unit | O17: Specific Embodied Energy (Btu/unit) (for this material) | P17: Specific Embodied Carbon (CO2-eq/unit) (for this material) | Q17: Specific Cost ($/unit) (for this material) | R17: Embodied Energy (MMBtu) (per reference volume of product) | S17: Embodied Carbon (lbs CO2-eq) (per reference volume of product) | T17: Cost ($) (per reference volume of product)
B18: Lubrication | C18: 2.34 | D18: kg | E18: 80564.445 | F18: 4.71325 | G18: 6 | H18: =IF(B18<>"",C18*E18*0.000001,"") -> 0.1885208 | I18: =IF(B18<>"",C18*F18,"") -> 11.029005 | J18: =IF(B18<>"",C18*G18,"") -> 14.04 | L18: City water supply to evaporative condensers | M18: =B47 -> 17010.309 | N18: gallons | O18: =B89 -> 17.939392 | P18: =B94 -> 0.0025036189 | Q18: =B69/1000 -> 0.002 | R18: =IF(L18<>"",M18*O18*0.000001,"") -> 0.3051546 | S18: =IF(L18<>"",M18*P18,"") -> 42.587331 | T18: =IF(L18<>"",M18*Q18,"") -> 34.020619
B19: Copper | C19: =Q49 -> 0.36730356 | D19: kg | E19: =R49 -> 39808.319 | F19: =S49 -> 2.6 | H19: =IF(B19<>"",C19*E19*0.000001,"") -> 0.014621737 | I19: =IF(B19<>"",C19*F19,"") -> 0.95498926 | J19: =IF(B19<>"",C19*G19,"") -> 0 | L19: Biocide chemical additon to cooling loop for micro mitigation | M19: =C66 -> 3.322326 | N19: gallons | O19: =B84 -> 119.56102 | P19: =B104 -> 0.013231125 | Q19: =B74 -> 19.090909 | R19: =IF(L19<>"",M19*O19*0.000001,"") -> 0.0003972207 | S19: =IF(L19<>"",M19*P19,"") -> 0.043958111 | T19: =IF(L19<>"",M19*Q19,"") -> 63.426224
B20: Elastomer | C20: =Q50 -> 0.16056986 | D20: kg | E20: =R50 -> 94781.7 | F20: =S50 -> 5.545 | H20: =IF(B20<>"",C20*E20*0.000001,"") -> 0.015219085 | I20: =IF(B20<>"",C20*F20,"") -> 0.89035989 | J20: =IF(B20<>"",C20*G20,"") -> 0 | L20: Steel low Alloy | M20: =Q74 -> 0.31749784 | N20: kg | O20: =R74 -> 19051.1 | P20: 1.37 | R20: =IF(L20<>"",M20*O20*0.000001,"") -> 0.0060486831 | S20: =IF(L20<>"",M20*P20,"") -> 0.43497204 | T20: =IF(L20<>"",M20*Q20,"") -> 0
B21: HDPE | C21: =Q51 -> 0.0050178082 | D21: kg | E21: =R51 -> 69190.6 | F21: =S51 -> 1.57 | H21: =IF(B21<>"",C21*E21*0.000001,"") -> 0.00034718516 | I21: =IF(B21<>"",C21*F21,"") -> 0.0078779589 | J21: =IF(B21<>"",C21*G21,"") -> 0 | L21: Stainless Steel | M21: =Q75 -> 0.34946467 | N21: kg | O21: =R75 -> 53741.394 | P21: 6.15 | R21: =IF(L21<>"",M21*O21*0.000001,"") -> 0.018780718 | S21: =IF(L21<>"",M21*P21,"") -> 2.1492077 | T21: =IF(L21<>"",M21*Q21,"") -> 0
B22: Low alloyed steel | C22: =Q52 -> 0.32113973 | D22: kg | E22: =R52 -> 19051.124 | F22: =S52 -> 1.37 | H22: =IF(B22<>"",C22*E22*0.000001,"") -> 0.0061180728 | I22: =IF(B22<>"",C22*F22,"") -> 0.43996142 | J22: =IF(B22<>"",C22*G22,"") -> 0 | L22: Aluminium | M22: =Q76 -> 0.39875732 | N22: kg | O22: =R76 -> 146912.1 | P22: 9.16 | R22: =IF(L22<>"",M22*O22*0.000001,"") -> 0.058582275 | S22: =IF(L22<>"",M22*P22,"") -> 3.652617 | T22: =IF(L22<>"",M22*Q22,"") -> 0
B23: Lubricating Oil (Manufacturing) | C23: =Q53 -> 0.027096164 | D23: kg | E23: =R53 -> 80564.445 | F23: =S53 -> 4.71325 | H23: =IF(B23<>"",C23*E23*0.000001,"") -> 0.0021829874 | I23: =IF(B23<>"",C23*F23,"") -> 0.127711 | J23: =IF(B23<>"",C23*G23,"") -> 0 | L23: Bricks | M23: =Q77 -> 0.34626548 | N23: Bricks | O23: =R77 -> 2843.46 | P23: 0.24 | R23: =IF(L23<>"",M23*O23*0.000001,"") -> 0.00098459203 | S23: =IF(L23<>"",M23*P23,"") -> 0.083103714 | T23: =IF(L23<>"",M23*Q23,"") -> 0
B24: PVC | C24: =Q54 -> 0.016056986 | D24: kg | E24: =R54 -> 73171.48 | F24: =S54 -> 2.41 | H24: =IF(B24<>"",C24*E24*0.000001,"") -> 0.0011749135 | I24: =IF(B24<>"",C24*F24,"") -> 0.038697337 | J24: =IF(B24<>"",C24*G24,"") -> 0 | L24: Methacrylate | M24: =Q78 -> 0.28817819 | N24: kg | O24: =R78 -> 110079.81 | P24: 5.9 | R24: =IF(L24<>"",M24*O24*0.000001,"") -> 0.031722602 | S24: =IF(L24<>"",M24*P24,"") -> 1.7002513 | T24: =IF(L24<>"",M24*Q24,"") -> 0
B25: Reinforced Steel | C25: =Q55 -> 1.3046301 | D25: kg | E25: =R55 -> 19051.1 | F25: =S55 -> 1.37 | H25: =IF(B25<>"",C25*E25*0.000001,"") -> 0.024854639 | I25: =IF(B25<>"",C25*F25,"") -> 1.7873433 | J25: =IF(B25<>"",C25*G25,"") -> 0 | L25: Polyurethane | M25: =Q79 -> 0.025744085 | N25: kg | O25: =R79 -> 68337.822 | P25: 3.76 | R25: =IF(L25<>"",M25*O25*0.000001,"") -> 0.0017592947 | S25: =IF(L25<>"",M25*P25,"") -> 0.096797761 | T25: =IF(L25<>"",M25*Q25,"") -> 0
H26: =IF(B26<>"",C26*E26*0.000001,"") | I26: =IF(B26<>"",C26*F26,"") | J26: =IF(B26<>"",C26*G26,"") | L26: PVC | M26: =Q80 -> 0.49518472 | N26: kg | O26: =R80 -> 73171.704 | P26: 3.1 | R26: =IF(L26<>"",M26*O26*0.000001,"") -> 0.03623351 | S26: =IF(L26<>"",M26*P26,"") -> 1.5350726 | T26: =IF(L26<>"",M26*Q26,"") -> 0
H27: =IF(B27<>"",C27*E27*0.000001,"") | I27: =IF(B27<>"",C27*F27,"") | J27: =IF(B27<>"",C27*G27,"") | R27: =IF(L27<>"",M27*O27*0.000001,"") | S27: =IF(L27<>"",M27*P27,"") | T27: =IF(L27<>"",M27*Q27,"")
G28: Total embodied energy and cost for input materials: | H28: =SUM(H18:H27) -> 0.25303942 | I28: =SUM(I18:I27) -> 15.275945 | J28: =SUM(J18:J27) -> 14.04 | Q28: Total embodied energy and cost for input materials: | R28: =SUM(R18:R27) -> 0.4596635 | S28: =SUM(S18:S27) -> 52.283311 | T28: =SUM(T18:T27) -> 97.446843
B30: *The IPA team defines "embodied carbon" for a material as the 10-year Global Warming Potential (GWP) of greenhouse gas emissions associated with the material's extraction, processing, and manufacturing. IPCC 2013 (AR5) data are used for 10-year GWP emissions factors. Emissions are calculated automatically in MFI. If calculating independently, the latest IPCC data for GWP and combustion emissions factors are available in the Reference Data tab linked below:
B31: Reference Data: 10-Year GWP & Combustion Emission Factors
B33: References, Notes, and Assumptions
B35: List key references and assumptions used to prepare the data provided in this sheet. Add as many rows as needed. | C35: To determine Biocide dosing per unit of cooling water: https://www.unitedlabsinc.com/content/pdf/label/336label.pdf
C36: Biocide cost example: https://www.coolingtowerchemicals.com/Polymeric-Quaternary-Amine-p/4655.htm
C37: Embodied Energy of chlorine (common biocide): https://pubs.acs.org/doi/10.1021/es404300y#:~:text=The%20embodied%20energy%20is%20based,during%20the%20water%20treatment%20process.
C38: Embodied Energy and Carbon of water: https://www.ncbi.nlm.nih.gov/pmc/articles/PMC8933528/
C39: Embodied Carbon of chlorine (common biocide): https://legacy.winnipeg.ca/finance/findata/matmgt/documents/2012/682-2012/682-2012_Appendix_H-WSTP_South_End_Plant_Process_Selection_Report/Appendix%207.pdf
C40: Materials Embodied Energies: https://en.wikipedia.org/wiki/Embodied_energy
C41: Materials Embodied Energies II: https://greenbuildingencyclopaedia.uk/wp-content/uploads/2014/07/Full-BSRIA-ICE-guide.pdf
B44: Calculations
B45: 100000 | C45: gallons/day average water consumption at the brewery wastewater plant (based on institutional knowledge/experience) | M45: Material Cost Calculations Waste Heat Recovery System
B46: 0.5 | C46: assumed % of city water usage to evaporative condensers compared to total wastewater plant city water usage (based on institutional knowledge/experience)
B47: =M104 -> 17010.309 | C47: gallons/day of city water usage fed to evaporative condensers | M47: Material for a 5 kWh heat pump, converted to 366.3 kWh (Assuming Linear Scale Up)
...

Sheet Market
B1: U.S. DEPARTMENT OF ENERGY (DOE) OFFICE OF ENERGY EFFICIENCY AND RENEWABLE ENERGY (EERE)
B2: Techno-economic, Energy & Carbon Heuristic Tool for Early Stage Technologies (TECHTEST)
C3: Return to Planning Page
B4: Market Size
B6: Quantify the total size of the end-use product market. Provide calculations and references at the bottom of the sheet. The end-use product should be defined in the Benchmarking section of the Project Basics tab.
B8: Annual U.S. Production of End-use Product: | C8: =2*365*10000 -> 7300000 | D8: Million Gallons | E8: =IF(EndUse_Product<>""," of "&EndUse_Product&" per year","of (end-use product not yet defined) per year") -> of Cooled Waste Water per year
C9: (all U.S. production, all facilities) | D9: (units)
B11: If the new technology will NOT be deployed in an existing market, or there is not yet any U.S. production of the end-use product, explain below.
B12: Comments:
B14: Market Breakdown
B16: Estimate the percent market share for the new technology, the commercial benchmark, and other competing technologies: - In the "Current Conditions" column, estimate the market breakdown based on the current U.S. market. - In the "Overnight Adoption" column, estimate the market breakdown in a hypothetical "overnight adoption" marketplace where the new technology is fully deployed, but all other market conditions remain the same as the current U.S. market. The total market share in each column should sum to 100%.
C18: Technology* | D18: Product / Application*: | E18: Pre-Deployment | F18: Full Deployment
E19: Market Share (%): Current Conditions | F19: Market Share (%): "Target Potential Market at Full Deployment" Hypothetical Scenario
B20: New Technology: | C20: =New_Technology -> Waste Heat Recovery (Heat Pump) | D20: =New_Technology_Apps -> Cooled Waste Water | E20: 0 | F20: 1
B21: Commercial Benchmark: | C21: =Commercial_Benchmark -> Evaporative Condenser | D21: =Benchmark_Apps -> Cooled Waste Water | E21: 1 | F21: 0
B22: Other Competing Technologies: | C22: =Other_Competing -> 0 | D22: =Other_Competing_Apps -> 0
D23: Sum: | E23: =SUM(E20:E22) -> 1 | F23: =SUM(F20:F22) -> 1
B25: *Note that the technology and product definitions are imported from the Benchmarking section of the "Project Basics" tab. If any edits to these definitions are needed, please modify the definitions in that tab.
B27: References, Notes, and Assumptions
B29: List key references and assumptions used to prepare the data provided in this sheet. Add as many rows as needed.
B35: Calculations
B36: Use this section for project-specific calculations and detailed references supporting the data above. Add as many rows as needed.
B38: Assumed that there are 2 million gallons procceses per day per tower, and there are 10000 towers across the US.
B62: Return to Home Page

Sheet Manufacturing Energy
B1: U.S. DEPARTMENT OF ENERGY (DOE) OFFICE OF ENERGY EFFICIENCY AND RENEWABLE ENERGY (EERE)
B2: Techno-economic, Energy & Carbon Heuristic Tool for Early Stage Technologies (TECHTEST)
C3: Return to Planning Page
B4: Manufacturing Energy, Emissions, and Energy Costs
B5: Estimate onsite energy consumption (in the blue input cells) by energy/fuel type. Energy consumption totals should correspond to the reference volume of finished product, as provided in the Ref Volume tab. Follow the same process for the new technology (left) and commercial benchmark technology (right) to facilitate comparisons. Default data are provided for energy prices, GWP, and source-to-site ratios (in the violet cells). These are based on industrial sector averages (see Summary Ref Tables tab) and can be user-adjusted from the default values for greater accuracy, if better estimates are available. IPCC AR5 values for 100-Year Global Warming Potential (GWP) are used to esimate the emissions associated with energy consumption. See the GWP & Combustion Data tab (linked below) for source data and assumptions.
C7: New Technology (at Industrial Scale) | M7: Commercial Benchmark
B8: Technology Name | C8: =New_Technology -> Waste Heat Recovery (Heat Pump) | L8: Technology Name | M8: =Commercial_Benchmark -> Evaporative Condenser
B9: Specific Product | C9: =New_Technology_Apps -> Cooled Waste Water | L9: Specific Product | M9: =Benchmark_Apps -> Cooled Waste Water
B10: Reference Volume | C10: =Ref_Volume -> 2 | D10: =Ref_Volume_Unit -> Million Gallons | L10: Reference Volume | M10: =Ref_Volume_Benchmark -> 2 | N10: =Ref_Volume_Unit -> Million Gallons
C11: (ref volume) | D11: (units) | M11: (ref volume) | N11: (units)
B13: New Technology - Energy Consumption & Cost Data (to produce reference volume) | L13: Commercial Benchmark - Energy Consumption & Cost Data (to produce reference volume)
D14: Data entry | E14: Default sector data* (Can be modified if needed. If modifying value, change background color to blue) | N14: Data entry | O14: Default sector data* (Can be modified if needed. If modifying value, change background color to blue)
D15: ↓ | N15: ↓
B16: Fuel or Energy Type | C16: Energy Source (Dropdowns available for Petroleum, Coal, and Renewable) | D16: Onsite Energy Consumption* (MMBtu) | E16: Specific Price ($/MMBtu) | F16: Specific 100-yr GWP (lb CO2-eq / MMBtu) | G16: Source-to-Site Ratio (electricity and steam only) | H16: Primary Energy Consumption, including offsite losses (MMBtu) | I16: Energy Cost ($) | J16: GWP Emissions (lb CO2-eq) | L16: Fuel or Energy Type | M16: Energy Source (Dropdowns available for Petroleum, Coal, and Renewable) | N16: Onsite Energy Consumption* (MMBtu) | O16: Specific Price ($/MMBtu) | P16: Specific 100-yr GWP (lb CO2-eq / MMBtu) | Q16: Source-to-Site Ratio (electricity and steam only) | R16: Primary Energy Consumption, including offsite losses (MMBtu) | S16: Energy Cost ($) | T16: GWP Emissions (lb CO2-eq)
B17: Electricity | C17: Electricity | D17: =F61*C69 -> 0.0048050532 | E17: =IF(ISNUMBER('Summary Ref Tables'!J8),'Summary Ref Tables'!J8,"") -> 21.043376 | F17: ='Grid Mix Customization'!F31 -> 108.58735 | G17: ='Summary Ref Tables'!F8 -> 2.8593558 | H17: =IF(D17<>"",D17*G17,"") -> 0.013739356 | I17: =IF(D17<>"",D17*E17,"") -> 0.10111454 | J17: =IF(D17<>"",D17*F17,"") -> 0.52176797 | L17: Electricity | M17: Electricity | N17: =B82+D17 -> 0.37120338 | O17: =IF(ISNUMBER('Summary Ref Tables'!J8),'Summary Ref Tables'!J8,"") -> 21.043376 | P17: ='Grid Mix Customization'!F31 -> 108.58735 | Q17: ='Summary Ref Tables'!F8 -> 2.8593558 | R17: =IF(N17<>"",N17*Q17,"") -> 1.0614025 | S17: =IF(N17<>"",N17*O17,"") -> 7.8113723 | T17: =IF(N17<>"",N17*P17,"") -> 40.30799
B18: Petroleum | C18: Diesel & distillate fuel oil | E18: =INDEX('Summary Ref Tables'!J9:J16,MATCH(C18,'Summary Ref Tables'!E9:E16,0)) -> 18.343154 | F18: =INDEX('Summary Ref Tables'!K9:K16,MATCH(C18,'Summary Ref Tables'!E9:E16,0)) -> 172.926 | G18: ='Summary Ref Tables'!F9 -> 1 | H18: =IF(D18<>"",D18*G18,"") | I18: =IF(D18<>"",D18*E18,"") | J18: =IF(D18<>"",D18*F18,"") | L18: Petroleum | M18: Diesel & distillate fuel oil | O18: =INDEX('Summary Ref Tables'!J9:J16,MATCH(M18,'Summary Ref Tables'!E9:E16,0)) -> 18.343154 | P18: =INDEX('Summary Ref Tables'!K9:K16,MATCH(M18,'Summary Ref Tables'!E9:E16,0)) -> 172.926 | Q18: ='Summary Ref Tables'!F9 -> 1 | R18: =IF(N18<>"",N18*Q18,"") | S18: =IF(N18<>"",N18*O18,"") | T18: =IF(N18<>"",N18*P18,"")
B19: Coal | C19: Anthracite | E19: =INDEX('Summary Ref Tables'!J17:J20,MATCH(C19,'Summary Ref Tables'!E17:E20,0)) -> 6.5924774 | F19: =INDEX('Summary Ref Tables'!K17:K20,MATCH(C19,'Summary Ref Tables'!E17:E20,0)) -> 229.7867 | G19: ='Summary Ref Tables'!F17 -> 1 | H19: =IF(D19<>"",D19*G19,"") | I19: =IF(D19<>"",D19*E19,"") | J19: =IF(D19<>"",D19*F19,"") | L19: Coal | M19: Anthracite | O19: =INDEX('Summary Ref Tables'!J17:J20,MATCH(M19,'Summary Ref Tables'!E17:E20,0)) -> 6.5924774 | P19: =INDEX('Summary Ref Tables'!K17:K20,MATCH(M19,'Summary Ref Tables'!E17:E20,0)) -> 229.7867 | Q19: ='Summary Ref Tables'!F17 -> 1 | R19: =IF(N19<>"",N19*Q19,"") | S19: =IF(N19<>"",N19*O19,"") | T19: =IF(N19<>"",N19*P19,"")
B20: Natural Gas | C20: Natural Gas | D20: =F62*C69 -> 0.01334737 | E20: =IF(ISNUMBER('Summary Ref Tables'!J21),'Summary Ref Tables'!J21,"") -> 5.7940327 | F20: ='Summary Ref Tables'!K21 -> 130.6149 | G20: ='Summary Ref Tables'!F21 -> 1 | H20: =IF(D20<>"",D20*G20,"") -> 0.01334737 | I20: =IF(D20<>"",D20*E20,"") -> 0.077335098 | J20: =IF(D20<>"",D20*F20,"") -> 1.7433654 | L20: Natural Gas | M20: Natural Gas | N20: =D20 -> 0.01334737 | O20: ='Summary Ref Tables'!J21 -> 5.7940327 | P20: ='Summary Ref Tables'!K21 -> 130.6149 | Q20: ='Summary Ref Tables'!F21 -> 1 | R20: =IF(N20<>"",N20*Q20,"") -> 0.01334737 | S20: =IF(N20<>"",N20*O20,"") -> 0.077335098 | T20: =IF(N20<>"",N20*P20,"") -> 1.7433654
B21: Renewable | C21: Wood Biomass | E21: =INDEX('Summary Ref Tables'!I22:I30,MATCH(C21,'Summary Ref Tables'!E22:E30,0)) -> 2.89 | F21: =INDEX('Summary Ref Tables'!K22:K30,MATCH(C21,'Summary Ref Tables'!E22:E30,0)) -> 264.93605 | G21: ='Summary Ref Tables'!F19 -> 1 | H21: =IF(D21<>"",D21*G21,"") | I21: =IF(D21<>"",D21*E21,"") | J21: =IF(D21<>"",D21*F21,"") | L21: Renewable | M21: Wood Biomass | O21: =INDEX('Summary Ref Tables'!J22:J30,MATCH(M21,'Summary Ref Tables'!E22:E30,0)) -> 2.89 | P21: =INDEX('Summary Ref Tables'!K22:K30,MATCH(M21,'Summary Ref Tables'!E22:E30,0)) -> 264.93605 | Q21: ='Summary Ref Tables'!F19 -> 1 | R21: =IF(N21<>"",N21*Q21,"") | S21: =IF(N21<>"",N21*O21,"") | T21: =IF(N21<>"",N21*P21,"")
B22: Steam | C22: Steam and Hot Water** | E22: =IF(ISNUMBER('Summary Ref Tables'!J30),'Summary Ref Tables'!J30,"") -> 4.7 | F22: ='Summary Ref Tables'!K30 -> 146.39001 | G22: ='Summary Ref Tables'!F30 -> 1.1992 | H22: =IF(D22<>"",D22*G22,"") | I22: =IF(D22<>"",D22*E22,"") | J22: =IF(D22<>"",D22*F22,"") | L22: Steam | M22: Steam and Hot Water** | O22: =IF(ISNUMBER('Summary Ref Tables'!J30),'Summary Ref Tables'!J30,"") -> 4.7 | P22: ='Summary Ref Tables'!K30 -> 146.39001 | Q22: ='Summary Ref Tables'!F30 -> 1.1992 | R22: =IF(N22<>"",N22*Q22,"") | S22: =IF(N22<>"",N22*O22,"") | T22: =IF(N22<>"",N22*P22,"")
B23: Custom Input I | E23: =IF(C23="","",INDEX('Summary Ref Tables'!J8:J30,MATCH(C23,'Summary Ref Tables'!E8:E30,0))) | F23: =IF(C23="","",INDEX('Summary Ref Tables'!K8:K30,MATCH(C23,'Summary Ref Tables'!E8:E30,0))) | G23: =IF(C23="","",INDEX('Summary Ref Tables'!F8:F30,MATCH(C23,'Summary Ref Tables'!E8:E30,0))) | H23: =IF(D23<>"",D23*G23,"") | I23: =IF(D23<>"",D23*E23,"") | J23: =IF(D23<>"",D23*F23,"") | L23: Custom Input I | O23: =IF(M23="","",INDEX('Summary Ref Tables'!J8:J30,MATCH(M23,'Summary Ref Tables'!E8:E30,0))) | P23: =IF(M23="","",INDEX('Summary Ref Tables'!K8:K30,MATCH(M23,'Summary Ref Tables'!E8:E30,0))) | Q23: =IF(M23="","",INDEX('Summary Ref Tables'!F8:F30,MATCH(M23,'Summary Ref Tables'!E8:E30,0))) | R23: =IF(N23<>"",N23*Q23,"") | S23: =IF(N23<>"",N23*O23,"") | T23: =IF(N23<>"",N23*P23,"")
B24: Custom Input II | E24: =IF(C24="","",INDEX('Summary Ref Tables'!J8:J30,MATCH(C24,'Summary Ref Tables'!E8:E30,0))) | F24: =IF(C24="","",INDEX('Summary Ref Tables'!K8:K30,MATCH(C24,'Summary Ref Tables'!E8:E30,0))) | G24: =IF(C24="","",INDEX('Summary Ref Tables'!F8:F30,MATCH(C24,'Summary Ref Tables'!E8:E30,0))) | H24: =IF(D24<>"",D24*G24,"") | I24: =IF(D24<>"",D24*E24,"") | J24: =IF(D24<>"",D24*F24,"") | L24: Custom Input II | M24: Liquified Petroleum Gas | O24: =IF(M24="","",INDEX('Summary Ref Tables'!J8:J30,MATCH(M24,'Summary Ref Tables'!E8:E30,0))) -> 12.217275 | P24: =IF(M24="","",INDEX('Summary Ref Tables'!K8:K30,MATCH(M24,'Summary Ref Tables'!E8:E30,0))) -> 146.8969 | Q24: =IF(M24="","",INDEX('Summary Ref Tables'!F8:F30,MATCH(M24,'Summary Ref Tables'!E8:E30,0))) -> 1 | R24: =IF(N24<>"",N24*Q24,"") | S24: =IF(N24<>"",N24*O24,"") | T24: =IF(N24<>"",N24*P24,"")
B25: Custom Input III | C25: Petroleum Coke | E25: =IF(C25="","",INDEX('Summary Ref Tables'!J8:J30,MATCH(C25,'Summary Ref Tables'!E8:E30,0))) -> 4.3129584 | F25: =IF(C25="","",INDEX('Summary Ref Tables'!K8:K30,MATCH(C25,'Summary Ref Tables'!E8:E30,0))) -> 227.3544 | G25: =IF(C25="","",INDEX('Summary Ref Tables'!F8:F30,MATCH(C25,'Summary Ref Tables'!E8:E30,0))) -> 1 | H25: =IF(D25<>"",D25*G25,"") | I25: =IF(D25<>"",D25*E25,"") | J25: =IF(D25<>"",D25*F25,"") | L25: Custom Input III | O25: =IF(M25="","",INDEX('Summary Ref Tables'!J8:J30,MATCH(M25,'Summary Ref Tables'!E8:E30,0))) | P25: =IF(M25="","",INDEX('Summary Ref Tables'!K8:K30,MATCH(M25,'Summary Ref Tables'!E8:E30,0))) | Q25: =IF(M25="","",INDEX('Summary Ref Tables'!F8:F30,MATCH(M25,'Summary Ref Tables'!E8:E30,0))) | R25: =IF(N25<>"",N25*Q25,"") | S25: =IF(N25<>"",N25*O25,"") | T25: =IF(N25<>"",N25*P25,"")
H26: =SUM(H17:H25) -> 0.027086726 | I26: =SUM(I17:I25) -> 0.17844964 | J26: =SUM(J17:J25) -> 2.2651334 | R26: =SUM(R17:R25) -> 1.0747499 | S26: =SUM(S17:S25) -> 7.8887074 | T26: =SUM(T17:T25) -> 42.051355
B27: * Link to reference data tab
B28: ** To avoid double-counting, only enter Steam data in this row if fuel/electricity used to generate the steam is not already included above.
B30: Manufacturing Process Emissions (if applicable)
B31: If there are process emissions associated with either the new technology or commercial benchmark technology, list the emissions and associated 100-year GWP below. Do not include any emissions associated with combustion of fuels (already captured above). If there are no significant process emissions, leave this section blank.
C33: New Technology - Process Emissions (to produce reference volume) | M33: Commercial Benchmark - Process Emissions (to produce reference volume)
C34: Emission Type (chemical name or acronym) | D34: Amount emitted (lb) | E34: 100-Year GWP* | F34: Suggested 100-Year GWP | G34: Embodied Carbon (lb CO2-eq) | M34: Emission Type (chemical name or acronym) | N34: Amount emitted (lb) | O34: 100-Year GWP* | P34: Suggested 100-Year GWP | Q34: Embodied Carbon (lb CO2-eq)
C35: R-134a | D35: 0.049174521 | E35: 1300 | F35: {=_xlfn.SWITCH(C35,'GWP Ref Tables'!D8,'GWP Ref Tables'!E8,'GWP Ref Tables'!D9,CH4_GWP,'GWP Ref Tables'!D10,N2O_GWP,'GWP Ref Tables'!D11,'GWP Ref Tables'!E11,'GWP Ref Tables'!D12,'GWP Ref Tables'!E12,"")} | G35: =IF(C35<>"",D35*E35,"") -> 63.926877 | P35: {=_xlfn.SWITCH(M35,'GWP Ref Tables'!D8,'GWP Ref Tables'!E8,'GWP Ref Tables'!D9,CH4_GWP,'GWP Ref Tables'!D10,N2O_GWP,'GWP Ref Tables'!D11,'GWP Ref Tables'!E11,'GWP Ref Tables'!D12,'GWP Ref Tables'!E12,"")} | Q35: =IF(M35<>"",N35*O35,"")
F36: {=_xlfn.SWITCH(C36,'GWP Ref Tables'!D8,'GWP Ref Tables'!E8,'GWP Ref Tables'!D9,CH4_GWP,'GWP Ref Tables'!D10,N2O_GWP,'GWP Ref Tables'!D11,'GWP Ref Tables'!E11,'GWP Ref Tables'!D12,'GWP Ref Tables'!E12,"")} | G36: =IF(C36<>"",D36*E36,"") | P36: {=_xlfn.SWITCH(M36,'GWP Ref Tables'!D9,'GWP Ref Tables'!E9,'GWP Ref Tables'!D10,CH4_GWP,'GWP Ref Tables'!D11,N2O_GWP,'GWP Ref Tables'!D12,'GWP Ref Tables'!E12,'GWP Ref Tables'!D13,'GWP Ref Tables'!E13,"")} -> 0 | Q36: =IF(M36<>"",N36*O36,"")
F37: {=_xlfn.SWITCH(C37,'GWP Ref Tables'!D8,'GWP Ref Tables'!E8,'GWP Ref Tables'!D9,CH4_GWP,'GWP Ref Tables'!D10,N2O_GWP,'GWP Ref Tables'!D11,'GWP Ref Tables'!E11,'GWP Ref Tables'!D12,'GWP Ref Tables'!E12,"")} | G37: =IF(C37<>"",D37*E37,"") | P37: {=_xlfn.SWITCH(M37,'GWP Ref Tables'!D10,'GWP Ref Tables'!E10,'GWP Ref Tables'!D11,CH4_GWP,'GWP Ref Tables'!D12,N2O_GWP,'GWP Ref Tables'!D13,'GWP Ref Tables'!E13,'GWP Ref Tables'!D14,'GWP Ref Tables'!E14,"")} -> 0 | Q37: =IF(M37<>"",N37*O37,"")
F38: Total: | G38: =SUM(G35:G37) -> 63.926877 | P38: Total | Q38: =SUM(Q35:Q37) -> 0
C40: * Use IPCC AR5 values for 100-Year Global Warming Potential (GWP). See the GWP Data tab (linked below) for excerpted GWP values for the most common emissions types, and a link to the full IPCC report for a complete list.
C41: Reference Data Tables: Global Warming Potential
B43: References, Notes, and Assumptions
B45: List key references and assumptions used to prepare the data provided in this sheet. Add as many rows as needed. | C45: Residential Heat Pump LCA from 2022:
C46: https://reader.elsevier.com/reader/sd/pii/S2212827122000580?token=494650C2CFA0DC2FF939A96C42BEA8B301FCFD6FBACF9839DDD737C0FF902E07A5E5444A7DDD55D24AFA2FEA0A34E46F&originRegion=us-east-1&originCreation=20230110001925
C47: https://ww2.arb.ca.gov/resources/documents/high-gwp-refrigerants
...

Sheet Use Phase Energy
B1: U.S. DEPARTMENT OF ENERGY (DOE) OFFICE OF ENERGY EFFICIENCY AND RENEWABLE ENERGY (EERE)
B2: Techno-economic, Energy & Carbon Heuristic Tool for Early Stage Technologies (TECHTEST)
C3: Return to Planning Page
B4: Use Phase Energy and Emissions
B6: Complete this tab for any technology expected to have an energy impact during final use of the finished product in its end-use sector. Technologies for which the Use Phase is important include energy-consuming devices or systems, energy-producing devices or systems, or material/component inputs to such systems. For example, a lightweight material may provide fuel savings (compared to typical materials) when used in a vehicle; and an energy-efficient device may provide electricity savings (compared to typical devices) when used in a consumer application. If the technology is not expected to have use phase impacts, leave this section blank. Technologies for which the Use Phase is not expected to be important include technologies where the end-use product is identical to that produced using current typical technologies. For example, a new production route for a commodity chemical would not be expected to have use phase impacts because the end-use product (the commodity chemical) is identical. To evaluate the use phase energy impact, estimate the total U.S. annual energy consumption (for the end-use market impacted by the technology) based on two scenarios:
B7: 1. Current Annual Energy Consumption
B8: 2. Hypothetical Annual Energy Consumption, Based on "Overnight Replacement" with New Technology
B9: In the "Current" scenario, assume the current market size and market conditions. Consider the entire market, including all facilities and manufacturers. In the "Overnight Replacement" scenario, assume a hypothetical market in which the new technology was immediately and fully deployed (at its maximum anticipated market share), with the market size and all other market conditions held constant (this is a simplification). Enter data on an annual basis in the blue cells below, considering the U.S. market and breaking down by sector and energy source. Enter data only into rows for sector(s) and energy sources applicable to the technology. For convenience, sector-average values for GWP and source-to-site ratio (based on EIA and IPCC reference data) are provided in the purple cells. These data may be over-written if more accurate facility- or industry-specific data are available. Provide your references, assumptions, source data, and calculations in the sections at the bottom of this tab.
D11: Default sector data* (can be modified if needed) | F11: Data entry** ↓ | K11: Data entry** ↓
D12: ↓ | E12: ↓ | F12: Current Annual U.S. Energy & Emissions - Product Use Phase (based on current technologies in use) | K12: Hypothetical Annual Energy & Emissions - Product Use Phase (based on "overnight replacement" with new technology)
B13: Sector & Energy Type | C13: Energy Source | D13: Specific 100-yr GWP (lb CO2-eq / MMBtu) | E13: Source-to-Site Ratio (Btu primary / Btu onsite) | F13: Annual Onsite Energy Consumption (MMBtu) | G13: Specific Price ($/MMBtu) | H13: Annual Primary Energy Consumption, including offsite losses (MMBtu) | I13: Annual Associated Cost ($) | J13: Annual Associated GWP Emissions (tons CO2-eq) | K13: Annual Energy Consumption (fuel specific units) | L13: Specific Price ($/MMBtu) | M13: Annual Primary Energy Consumption (MMBtu) | N13: Annual Associated Cost ($) | O13: Annual Associated GWP Emissions (tons CO2-eq)
B14: Industrial Sector | H14: =IF(F14<>"",(F14*#REF!)/1000000,"") | J14: =IF(H14<>"",(H14*E14)/1000000,"") | M14: =IF(K14<>"",(K14*F14)/1000000,"")
B15: Electricity | C15: Electricity | D15: ='Grid Mix Customization'!F31 -> 108.58735 | E15: ='Summary Ref Tables'!F8 -> 2.8593558 | F15: =D51*US_Annual_Production/Ref_Volume -> 44577450 | G15: =IF(ISNUMBER('Summary Ref Tables'!J8),'Summary Ref Tables'!J8,"") -> 21.043376 | H15: =IF(F15<>"",F15*$E15,"") -> 1.2746279e+08 | I15: =IF(F15<>"",G15*$F15,"") -> 9.3806006e+08 | J15: =IF(F15<>"",F15*$D15*0.0005,"") -> 2420273.5 | K15: =C93*US_Annual_Production/Ref_Volume -> 1.0813019e+08 | L15: =IF(ISNUMBER('Summary Ref Tables'!J8),'Summary Ref Tables'!J8,"") -> 21.043376 | M15: =IF(K15<>"",K15*$E15,"") -> 3.0918269e+08 | N15: =IF(K15<>"",L15*$K15,"") -> 2.2754243e+09 | O15: =IF(K15<>"",K15*$D15*0.0005,"") -> 5870785.4
B16: Petroleum Look Up | C16: Motor Gasoline | D16: =INDEX('Summary Ref Tables'!K9:K16,MATCH(C16,'Summary Ref Tables'!E9:E16,0)) -> 161.7612 | E16: 1 | G16: =INDEX('Summary Ref Tables'!J9:J16,MATCH(C16,'Summary Ref Tables'!E9:E16,0)) -> 21.540594 | H16: =IF(F16<>"",F16*$E16,"") | I16: =IF(F16<>"",G16*$F16,"") | J16: =IF(F16<>"",F16*$D16*0.0005,"") | L16: =INDEX('Summary Ref Tables'!J9:J16,MATCH(C16,'Summary Ref Tables'!E9:E16,0)) -> 21.540594 | M16: =IF(K16<>"",K16*$E16,"") | N16: =IF(K16<>"",L16*$K16,"") | O16: =IF(K16<>"",K16*$D16*0.0005,"")
B17: Coal Look Up | C17: Coal Coke | D17: =INDEX('Summary Ref Tables'!K17:K20,MATCH(C17,'Summary Ref Tables'!E17:E20,0)) -> 250.46252 | E17: ='Summary Ref Tables'!F17 -> 1 | G17: =INDEX('Summary Ref Tables'!J17:J20,MATCH(C17,'Summary Ref Tables'!E17:E20,0)) -> 7.661341 | H17: =IF(F17<>"",F17*$E17,"") | I17: =IF(F17<>"",G17*$F17,"") | J17: =IF(F17<>"",F17*$D17*0.0005,"") | L17: =INDEX('Summary Ref Tables'!J17:J20,MATCH(C17,'Summary Ref Tables'!E17:E20,0)) -> 7.661341 | M17: =IF(K17<>"",K17*$E17,"") | N17: =IF(K17<>"",L17*$K17,"") | O17: =IF(K17<>"",K17*$D17*0.0005,"")
B18: Natural Gas | C18: Natural Gas | D18: ='Summary Ref Tables'!K21 -> 130.6149 | E18: ='Summary Ref Tables'!F21 -> 1 | G18: =IF(ISNUMBER('Summary Ref Tables'!J21),'Summary Ref Tables'!J21,"") -> 5.7940327 | H18: =IF(F18<>"",F18*$E18,"") | I18: =IF(F18<>"",G18*$F18,"") | J18: =IF(F18<>"",F18*$D18*0.0005,"") | K18: =(C98*-1)*US_Annual_Production/Ref_Volume -> -2.227717e+08 | L18: =IF(ISNUMBER('Summary Ref Tables'!J21),'Summary Ref Tables'!J21,"") -> 5.7940327 | M18: =IF(K18<>"",K18*$E18,"") -> -2.227717e+08 | N18: =IF(K18<>"",L18*$K18,"") -> -1.2907465e+09 | O18: =IF(K18<>"",K18*$D18*0.0005,"") -> -14548652
B19: Renewable Look Up | C19: Solar | D19: =INDEX('Summary Ref Tables'!K22:K29,MATCH(C19,'Summary Ref Tables'!E22:E29,0)) -> 31.015814 | E19: ='Summary Ref Tables'!F22 -> 1 | G19: =INDEX('Summary Ref Tables'!J22:J29,MATCH(C19,'Summary Ref Tables'!E22:E29,0)) -> 14.067408 | H19: =IF(F19<>"",F19*$E19,"") | I19: =IF(F19<>"",G19*$F19,"") | J19: =IF(F19<>"",F19*$D19*0.0005,"") | L19: =INDEX('Summary Ref Tables'!J22:J29,MATCH(C19,'Summary Ref Tables'!E22:E29,0)) -> 14.067408 | M19: =IF(K19<>"",K19*$E19,"") | N19: =IF(K19<>"",L19*$K19,"") | O19: =IF(K19<>"",K19*$D19*0.0005,"")
B20: Steam | C20: Steam and Hot Water* | D20: ='Summary Ref Tables'!K30 -> 146.39001 | E20: ='Summary Ref Tables'!F30 -> 1.1992 | G20: =IF(ISNUMBER('Summary Ref Tables'!J30),'Summary Ref Tables'!J30,"") -> 4.7 | H20: =IF(F20<>"",F20*$E20,"") | I20: =IF(F20<>"",G20*$F20,"") | J20: =IF(F20<>"",F20*$D20*0.0005,"") | L20: =IF(ISNUMBER('Summary Ref Tables'!J30),'Summary Ref Tables'!J30,"") -> 4.7 | M20: =IF(K20<>"",K20*$E20,"") | N20: =IF(K20<>"",L20*$K20,"") | O20: =IF(K20<>"",K20*$D20*0.0005,"")
B21: Custom Input I | D21: =IF(C21="","",INDEX('Summary Ref Tables'!K8:K30,MATCH(C21,'Summary Ref Tables'!E8:E30,0))) | E21: =IF(C21="","",INDEX('Summary Ref Tables'!F8:F30,MATCH(C21,'Summary Ref Tables'!E8:E30,0))) | G21: =IF(C21="","",INDEX('Summary Ref Tables'!J8:J30,MATCH(C21,'Summary Ref Tables'!E8:E30,0))) | H21: =IF(F21<>"",F21*$E21,"") | I21: =IF(F21<>"",G21*$F21,"") | J21: =IF(F21<>"",F21*$D21*0.0005,"") | L21: =IF(C21="","",INDEX('Summary Ref Tables'!J8:J30,MATCH(C21,'Summary Ref Tables'!E8:E30,0))) | M21: =IF(K21<>"",K21*$E21,"") | N21: =IF(K21<>"",L21*$K21,"") | O21: =IF(K21<>"",K21*$D21*0.0005,"")
B22: Custom Input II | D22: =IF(C22="","",INDEX('Summary Ref Tables'!K8:K30,MATCH(C22,'Summary Ref Tables'!E8:E30,0))) | E22: =IF(C22="","",INDEX('Summary Ref Tables'!F8:F30,MATCH(C22,'Summary Ref Tables'!E8:E30,0))) | G22: =IF(C22="","",INDEX('Summary Ref Tables'!J8:J30,MATCH(C22,'Summary Ref Tables'!E8:E30,0))) | H22: =IF(F22<>"",F22*$E22,"") | I22: =IF(F22<>"",G22*$F22,"") | J22: =IF(F22<>"",F22*$D22*0.0005,"") | L22: =IF(C22="","",INDEX('Summary Ref Tables'!J8:J30,MATCH(C22,'Summary Ref Tables'!E8:E30,0))) | M22: =IF(K22<>"",K22*$E22,"") | N22: =IF(K22<>"",L22*$K22,"") | O22: =IF(K22<>"",K22*$D22*0.0005,"")
B23: Custom Input III | D23: =IF(C23="","",INDEX('Summary Ref Tables'!K8:K30,MATCH(C23,'Summary Ref Tables'!E8:E30,0))) | E23: =IF(C23="","",INDEX('Summary Ref Tables'!F8:F30,MATCH(C23,'Summary Ref Tables'!E8:E30,0))) | G23: =IF(C23="","",INDEX('Summary Ref Tables'!J8:J30,MATCH(C23,'Summary Ref Tables'!E8:E30,0))) | H23: =IF(F23<>"",F23*$E23,"") | I23: =IF(F23<>"",G23*$F23,"") | J23: =IF(F23<>"",F23*$D23*0.0005,"") | L23: =IF(C23="","",INDEX('Summary Ref Tables'!J8:J30,MATCH(C23,'Summary Ref Tables'!E8:E30,0))) | M23: =IF(K23<>"",K23*$E23,"") | N23: =IF(K23<>"",L23*$K23,"") | O23: =IF(K23<>"",K23*$D23*0.0005,"")
B26: Transportation Sector | N26: =IF(G26<>"",L26*$K26,"")
B27: Electricity | C27: Electricity | D27: ='Grid Mix Customization'!F31 -> 108.58735 | E27: ='Summary Ref Tables'!F34 -> 2.8593799 | G27: =IF(ISNUMBER('Summary Ref Tables'!J34),'Summary Ref Tables'!J34,"") -> 21.043376 | H27: =IF(F27<>"",F27*$E27,"") | I27: =IF(F27<>"",G27*$F27,"") | J27: =IF(F27<>"",F27*$D27*0.0005,"") | L27: =IF(ISNUMBER('Summary Ref Tables'!J8),'Summary Ref Tables'!J8,"") -> 21.043376 | M27: =IF(K27<>"",K27*$E27,"") | N27: =IF(K27<>"",L27*$K27,"") | O27: =IF(K27<>"",K27*$D27*0.0005,"")
B28: Petroleum Look Up | C28: Motor gasoline | D28: =INDEX('Summary Ref Tables'!K35:K41,MATCH(C28,'Summary Ref Tables'!E35:E41,0)) -> 165.29626 | E28: ='Summary Ref Tables'!F35 -> 1 | G28: =INDEX('Summary Ref Tables'!J35:J41,MATCH(C28,'Summary Ref Tables'!E35:E41,0)) -> 18.638955 | H28: =IF(F28<>"",F28*$E28,"") | I28: =IF(F28<>"",G28*$F28,"") | J28: =IF(F28<>"",F28*$D28*0.0005,"") | L28: =INDEX('Summary Ref Tables'!J35:J41,MATCH(C28,'Summary Ref Tables'!E35:E41,0)) -> 18.638955 | M28: =IF(K28<>"",K28*$E28,"") | N28: =IF(K28<>"",L28*$K28,"") | O28: =IF(K28<>"",K28*$D28*0.0005,"")
B29: Natural Gas | C29: Natural Gas (pipelines and fuel) | D29: ='Summary Ref Tables'!K42 -> 138.17138 | E29: ='Summary Ref Tables'!F42 -> 1 | G29: =IF(ISNUMBER('Summary Ref Tables'!J21),'Summary Ref Tables'!J21,"") -> 5.7940327 | H29: =IF(F29<>"",F29*$E29,"") | I29: =IF(F29<>"",G29*$F29,"") | J29: =IF(F29<>"",F29*$D29*0.0005,"") | L29: =IF(ISNUMBER('Summary Ref Tables'!J21),'Summary Ref Tables'!J21,"") -> 5.7940327 | M29: =IF(K29<>"",K29*$E29,"") | N29: =IF(K29<>"",L29*$K29,"") | O29: =IF(K29<>"",K29*$D29*0.0005,"")
B30: Renewable Fuels | C30: Biomass | D30: ='Summary Ref Tables'!K43 -> 165.2502 | E30: ='Summary Ref Tables'!F43 -> 1 | G30: =IF(ISNUMBER('Summary Ref Tables'!J22),'Summary Ref Tables'!J22,"") -> 2.89 | H30: =IF(F30<>"",F30*$E30,"") | I30: =IF(F30<>"",G30*$F30,"") | J30: =IF(F30<>"",F30*$D30*0.0005,"") | L30: =IF(ISNUMBER('Summary Ref Tables'!J22),'Summary Ref Tables'!J22,"") -> 2.89 | M30: =IF(K30<>"",K30*$E30,"") | N30: =IF(K30<>"",L30*$K30,"") | O30: =IF(K30<>"",K30*$D30*0.0005,"")
B31: Custom Input I | D31: =IF(C31="","",INDEX('Summary Ref Tables'!K34:K43,MATCH(C31,'Summary Ref Tables'!E34:E43,0))) | E31: =IF(C31="","",INDEX('Summary Ref Tables'!F34:F43,MATCH(C31,'Summary Ref Tables'!E34:E43,0))) | G31: =IF(C31="","",INDEX('Summary Ref Tables'!J34:J43,MATCH(C31,'Summary Ref Tables'!E34:E43,0))) | H31: =IF(F31<>"",F31*$E31,"") | I31: =IF(F31<>"",G31*$F31,"") | J31: =IF(F31<>"",F31*$D31*0.0005,"") | L31: =IF(C31="","",INDEX('Summary Ref Tables'!J34:J43,MATCH(C31,'Summary Ref Tables'!E34:E43,0))) | M31: =IF(K31<>"",K31*$E31,"") | N31: =IF(K31<>"",L31*$K31,"") | O31: =IF(K31<>"",K31*$D31*0.0005,"")
B32: Custom Input II | D32: =IF(C32="","",INDEX('Summary Ref Tables'!K34:K43,MATCH(C32,'Summary Ref Tables'!E34:E43,0))) | E32: =IF(C32="","",INDEX('Summary Ref Tables'!F34:F43,MATCH(C32,'Summary Ref Tables'!E34:E43,0))) | G32: =IF(C32="","",INDEX('Summary Ref Tables'!J34:J43,MATCH(C32,'Summary Ref Tables'!E34:E43,0))) | H32: =IF(F32<>"",F32*$E32,"") | I32: =IF(F32<>"",G32*$F32,"") | J32: =IF(F32<>"",F32*$D32*0.0005,"") | L32: =IF(C32="","",INDEX('Summary Ref Tables'!J34:J43,MATCH(C32,'Summary Ref Tables'!E34:E43,0))) | M32: =IF(K32<>"",K32*$E32,"") | N32: =IF(K32<>"",L32*$K32,"") | O32: =IF(K32<>"",K32*$D32*0.0005,"")
B33: Custom Input III | D33: =IF(C33="","",INDEX('Summary Ref Tables'!K34:K43,MATCH(C33,'Summary Ref Tables'!E34:E43,0))) | E33: =IF(C33="","",INDEX('Summary Ref Tables'!F34:F43,MATCH(C33,'Summary Ref Tables'!E34:E43,0))) | G33: =IF(C33="","",INDEX('Summary Ref Tables'!J34:J43,MATCH(C33,'Summary Ref Tables'!E34:E43,0))) | H33: =IF(F33<>"",F33*$E33,"") | I33: =IF(F33<>"",G33*$F33,"") | J33: =IF(F33<>"",F33*$D33*0.0005,"") | L33: =IF(C33="","",INDEX('Summary Ref Tables'!J34:J43,MATCH(C33,'Summary Ref Tables'!E34:E43,0))) | M33: =IF(K33<>"",K33*$E33,"") | N33: =IF(K33<>"",L33*$K33,"") | O33: =IF(K33<>"",K33*$D33*0.0005,"")
F34: Current Annual Energy & Emissions: | H34: =SUM(H15:H33) -> 1.2746279e+08 | I34: =SUM(I15:I33) -> 9.3806006e+08 | J34: =SUM(J15:J33) -> 2420273.5 | K34: Hypothetical Annual Energy & Emissions: | M34: =SUM(M15:M33) -> 86410986 | N34: =SUM(N15:N33) -> 9.846778e+08 | O34: =SUM(O15:O33) -> -8677866.8
F35: or equivalently: | H35: =AnnualUsePhaseEnergy_Current*0.000001 -> 127.46279 | J35: =AnnualUsePhaseEmissions_Current*0.000001 -> 2.4202735 | K35: or equivalently: | M35: =AnnualUsePhaseEnergy_Hypoth*0.000001 -> 86.410986 | O35: =AnnualUsePhaseEmissions_Hypothetical*0.000001 -> -8.6778668
B36: *Link to reference data tab
B38: References, Notes, and Assumptions
